<robot name="2R_robot">
    <material name="blue">
        <color rgba="0 0 0.8 1"/>
    </material>
    <material name="black">
        <color rgba="0 0 0 1"/>
    </material>
    
    <link name="base_link">
        <inertial>
            <origin xyz="8e-05 0.02446 -0.00146" rpy="0 0 0"/>
            <mass value="1000000"/>
            <inertia ixx="0.00196" ixy="0" ixz="0" iyy="0.00133" iyz="-2e-05" izz="0.0023"/>
        </inertial>
        <visual>
            <geometry>
                <box size="0.7 0.7 0.10"/>
            </geometry>
        </visual>
        <collision>
            <origin xyz="0 0.00015 -0.00044" rpy="0 0 0"/>
            <geometry>
                <box size="0.7 0.7 0.10"/>
            </geometry>
        </collision>
    </link>
    <link name="link1">
        <visual>
            <geometry>
                <cylinder length="1" radius="0.05"/>
            </geometry>
            <origin rpy="0 0 0" xyz="0 0 0.55"/>
            <material name="white"/>
        </visual>
    </link>
    <joint name="joint1" type="revolute">
        <parent link="base_link"/>
        <child link="link1"/>
        <origin xyz="0 0 0.05" rpy="0.0 0.5 0.0"/>
        <limit effort="200" lower="-3.14" upper="3.14" velocity="1.0"/>
        <axis xyz= "1 0 0"/>
    </joint>
    <link name="link2">
        <visual>
            <geometry>
                <cylinder length="1" radius="0.05"/>
            </geometry>
            <origin rpy="0 0 0" xyz="0 0 0.5"/>
            <material name="blue"/>
        </visual>
    </link>
    <joint name="joint2" type="revolute">
        <parent link="link1"/>
        <child link="link2"/>
        <origin xyz="0 0 1.05" rpy="0.0 0.5 0.0"/>
        <limit effort="200" lower="-3.14" upper="3.14" velocity="1.0"/>
        <axis xyz= "1 0 0"/>
    </joint>
</robot>
